Workbook

Sheet Leia-me
A1: CRM relacional — Escritório › Gerente › Vendedor › Deal › Conta › Produto
A2: Todas as 4 tabelas do dataset ligadas com exatidão. Os números das abas de resumo são fórmulas sobre a aba Pipeline_Completo.
A4: PREMISSAS (editáveis)
A5: Data de referência ("hoje") | B5: 43100 | C5: Último dia com dados no dataset. Usada para calcular a idade dos deals abertos.
A6: Limite "Saudável" (dias) | B6: 88 | C6: Até aqui = dentro do tempo em que ~75% dos deals ganhos fecham (p75 do ciclo dos ganhos = 85 dias).
A7: Limite "Esfriando" (dias) | B7: 120 | C7: ~95% dos deals ganhos fecharam até 114 dias.
A8: Limite "Zumbi" (dias) | B8: 138 | C8: Maior ciclo de qualquer deal fechado no histórico. Acima disso nenhum deal jamais fechou.
A11: COMO AS TABELAS SE LIGAM
A12: sales_pipeline.sales_agent | B12: → sales_teams | C12: Cada deal tem 1 vendedor; cada vendedor tem 1 gerente e 1 escritório regional.
A13: sales_pipeline.product | B13: → products | C13: Preço de tabela e série. Corrigido: "GTXPro" (1.480 linhas) não existia em products → tratado como "GTX Pro".
A14: sales_pipeline.account | B14: → accounts | C14: Setor, receita, funcionários, país, empresa-mãe. 1.425 deals abertos NÃO têm conta preenchida.
A15: Hierarquia | B15: 3 › 6 › 35 | C15: 3 escritórios › 6 gerentes (2 por escritório) › 35 vendedores. 5 vendedores não têm nenhum deal.
A17: DEFINIÇÕES
A18: Receita ganha | C18: Soma de close_value dos deals Won (valor real fechado).
A19: Pipeline aberto (estimado) | C19: Deals Engaging + Prospecting não têm close_value. Usamos o preço de tabela do produto (nos ganhos, close_value ≈ preço de tabela, desvio médio < 1%).
A20: Win rate | C20: Won ÷ (Won + Lost). Atenção: deals iniciados em 2016 têm win rate inflado (82%) porque perdas antes de mar/2017 não estão no dataset.
A21: Relógio do deal | C21: Só para Engaging: Saudável / Esfriando / Última chance / Zumbi, pela idade na data de referência e pelos limites acima.
A22: Ciclo (dias) | C22: close_date − engage_date (deals fechados).
A24: ABAS
A25: Hierarquia | C25: Escritório › Gerente › Vendedor com todos os números de cada um, subtotais por gerente e escritório.
A26: Resumo_Escritorio / Resumo_Gerente | C26: Visão consolidada por nível.
A27: Produto_x_Gerente | C27: Receita ganha e pipeline aberto de cada produto, por equipe.
A28: Contas | C28: Cada conta com seus números e quantos vendedores/gerentes/escritórios mexem nela.
A29: Pipeline_Completo | C29: As 8.800 oportunidades com TODAS as colunas das 4 tabelas lado a lado (filtrável).
A30: Qualidade_Dados | C30: Problemas encontrados nos dados, com contagem.
A31: raw_* | C31: Os 4 CSVs originais, sem alteração, para auditoria.
A33: Legenda: texto azul com fundo amarelo = premissa editável. Demais números = fórmulas.

Sheet Hierarquia
A1: Escritório | B1: Gerente | C1: Vendedor | D1: Deals total | E1: Won | F1: Lost | G1: Engaging | H1: Prospecting | I1: Win rate | J1: Receita ganha (US$) | K1: Ticket médio ganho (US$) | L1: Pipeline aberto (US$) | M1: Engaging vivos (≤ limite zumbi) | N1: Valor vivos (US$) | O1: Zumbis | P1: Valor zumbi (US$) | Q1: % pipeline Engaging zumbi | R1: Abertos sem conta
A2: Central | B2: Dustin Brinkmann | C2: Anna Snelling | D2: =COUNTIFS(Pipeline_Completo!$D$2:$D$8801,$C2) -> 448 | E2: =COUNTIFS(Pipeline_Completo!$D$2:$D$8801,$C2,Pipeline_Completo!$O$2:$O$8801,"Won") -> 208 | F2: =COUNTIFS(Pipeline_Completo!$D$2:$D$8801,$C2,Pipeline_Completo!$O$2:$O$8801,"Lost") -> 128 | G2: =COUNTIFS(Pipeline_Completo!$D$2:$D$8801,$C2,Pipeline_Completo!$O$2:$O$8801,"Engaging") -> 57 | H2: =COUNTIFS(Pipeline_Completo!$D$2:$D$8801,$C2,Pipeline_Completo!$O$2:$O$8801,"Prospecting") -> 55 | I2: =IFERROR(E2/(E2+F2),"") -> 0.61904762 | J2: =SUMIFS(Pipeline_Completo!$R$2:$R$8801,Pipeline_Completo!$D$2:$D$8801,$C2,Pipeline_Completo!$O$2:$O$8801,"Won") -> 275056 | K2: =IFERROR(J2/E2,"") -> 1322.3846 | L2: =SUMIFS(Pipeline_Completo!$S$2:$S$8801,Pipeline_Completo!$D$2:$D$8801,$C2,Pipeline_Completo!$O$2:$O$8801,"Engaging")+SUMIFS(Pipeline_Completo!$S$2:$S$8801,Pipeline_Completo!$D$2:$D$8801,$C2,Pipeline_Completo!$O$2:$O$8801,"Prospecting") -> 173259 | M2: =COUNTIFS(Pipeline_Completo!$D$2:$D$8801,$C2,Pipeline_Completo!$V$2:$V$8801,"Saudável")+COUNTIFS(Pipeline_Completo!$D$2:$D$8801,$C2,Pipeline_Completo!$V$2:$V$8801,"Esfriando")+COUNTIFS(Pipeline_Completo!$D$2:$D$8801,$C2,Pipeline_Completo!$V$2:$V$8801,"Última chance") -> 1 | N2: =SUMIFS(Pipeline_Completo!$S$2:$S$8801,Pipeline_Completo!$D$2:$D$8801,$C2,Pipeline_Completo!$V$2:$V$8801,"Saudável")+SUMIFS(Pipeline_Completo!$S$2:$S$8801,Pipeline_Completo!$D$2:$D$8801,$C2,Pipeline_Completo!$V$2:$V$8801,"Esfriando")+SUMIFS(Pipeline_Completo!$S$2:$S$8801,Pipeline_Completo!$D$2:$D$8801,$C2,Pipeline_Completo!$V$2:$V$8801,"Última chance") -> 55 | O2: =COUNTIFS(Pipeline_Completo!$D$2:$D$8801,$C2,Pipeline_Completo!$V$2:$V$8801,"Zumbi") -> 56 | P2: =SUMIFS(Pipeline_Completo!$S$2:$S$8801,Pipeline_Completo!$D$2:$D$8801,$C2,Pipeline_Completo!$V$2:$V$8801,"Zumbi") -> 95359 | Q2: =IFERROR(P2/(N2+P2),"") -> 0.99942356 | R2: =COUNTIFS(Pipeline_Completo!$D$2:$D$8801,$C2,Pipeline_Completo!$O$2:$O$8801,"Engaging",Pipeline_Completo!$E$2:$E$8801,"")+COUNTIFS(Pipeline_Completo!$D$2:$D$8801,$C2,Pipeline_Completo!$O$2:$O$8801,"Prospecting",Pipeline_Completo!$E$2:$E$8801,"") -> 69
A3: Central | B3: Dustin Brinkmann | C3: Cecily Lampkin | D3: =COUNTIFS(Pipeline_Completo!$D$2:$D$8801,$C3) -> 203 | E3: =COUNTIFS(Pipeline_Completo!$D$2:$D$8801,$C3,Pipeline_Completo!$O$2:$O$8801,"Won") -> 107 | F3: =COUNTIFS(Pipeline_Completo!$D$2:$D$8801,$C3,Pipeline_Completo!$O$2:$O$8801,"Lost") -> 53 | G3: =COUNTIFS(Pipeline_Completo!$D$2:$D$8801,$C3,Pipeline_Completo!$O$2:$O$8801,"Engaging") -> 19 | H3: =COUNTIFS(Pipeline_Completo!$D$2:$D$8801,$C3,Pipeline_Completo!$O$2:$O$8801,"Prospecting") -> 24 | I3: =IFERROR(E3/(E3+F3),"") -> 0.66875 | J3: =SUMIFS(Pipeline_Completo!$R$2:$R$8801,Pipeline_Completo!$D$2:$D$8801,$C3,Pipeline_Completo!$O$2:$O$8801,"Won") -> 229800 | K3: =IFERROR(J3/E3,"") -> 2147.6636 | L3: =SUMIFS(Pipeline_Completo!$S$2:$S$8801,Pipeline_Completo!$D$2:$D$8801,$C3,Pipeline_Completo!$O$2:$O$8801,"Engaging")+SUMIFS(Pipeline_Completo!$S$2:$S$8801,Pipeline_Completo!$D$2:$D$8801,$C3,Pipeline_Completo!$O$2:$O$8801,"Prospecting") -> 86748 | M3: =COUNTIFS(Pipeline_Completo!$D$2:$D$8801,$C3,Pipeline_Completo!$V$2:$V$8801,"Saudável")+COUNTIFS(Pipeline_Completo!$D$2:$D$8801,$C3,Pipeline_Completo!$V$2:$V$8801,"Esfriando")+COUNTIFS(Pipeline_Completo!$D$2:$D$8801,$C3,Pipeline_Completo!$V$2:$V$8801,"Última chance") -> 0 | N3: =SUMIFS(Pipeline_Completo!$S$2:$S$8801,Pipeline_Completo!$D$2:$D$8801,$C3,Pipeline_Completo!$V$2:$V$8801,"Saudável")+SUMIFS(Pipeline_Completo!$S$2:$S$8801,Pipeline_Completo!$D$2:$D$8801,$C3,Pipeline_Completo!$V$2:$V$8801,"Esfriando")+SUMIFS(Pipeline_Completo!$S$2:$S$8801,Pipeline_Completo!$D$2:$D$8801,$C3,Pipeline_Completo!$V$2:$V$8801,"Última chance") -> 0 | O3: =COUNTIFS(Pipeline_Completo!$D$2:$D$8801,$C3,Pipeline_Completo!$V$2:$V$8801,"Zumbi") -> 19 | P3: =SUMIFS(Pipeline_Completo!$S$2:$S$8801,Pipeline_Completo!$D$2:$D$8801,$C3,Pipeline_Completo!$V$2:$V$8801,"Zumbi") -> 29565 | Q3: =IFERROR(P3/(N3+P3),"") -> 1 | R3: =COUNTIFS(Pipeline_Completo!$D$2:$D$8801,$C3,Pipeline_Completo!$O$2:$O$8801,"Engaging",Pipeline_Completo!$E$2:$E$8801,"")+COUNTIFS(Pipeline_Completo!$D$2:$D$8801,$C3,Pipeline_Completo!$O$2:$O$8801,"Prospecting",Pipeline_Completo!$E$2:$E$8801,"") -> 33
A4: Central | B4: Dustin Brinkmann | C4: Versie Hillebrand | D4: =COUNTIFS(Pipeline_Completo!$D$2:$D$8801,$C4) -> 361 | E4: =COUNTIFS(Pipeline_Completo!$D$2:$D$8801,$C4,Pipeline_Completo!$O$2:$O$8801,"Won") -> 176 | F4: =COUNTIFS(Pipeline_Completo!$D$2:$D$8801,$C4,Pipeline_Completo!$O$2:$O$8801,"Lost") -> 88 | G4: =COUNTIFS(Pipeline_Completo!$D$2:$D$8801,$C4,Pipeline_Completo!$O$2:$O$8801,"Engaging") -> 43 | H4: =COUNTIFS(Pipeline_Completo!$D$2:$D$8801,$C4,Pipeline_Completo!$O$2:$O$8801,"Prospecting") -> 54 | I4: =IFERROR(E4/(E4+F4),"") -> 0.66666667 | J4: =SUMIFS(Pipeline_Completo!$R$2:$R$8801,Pipeline_Completo!$D$2:$D$8801,$C4,Pipeline_Completo!$O$2:$O$8801,"Won") -> 187693 | K4: =IFERROR(J4/E4,"") -> 1066.4375 | L4: =SUMIFS(Pipeline_Completo!$S$2:$S$8801,Pipeline_Completo!$D$2:$D$8801,$C4,Pipeline_Completo!$O$2:$O$8801,"Engaging")+SUMIFS(Pipeline_Completo!$S$2:$S$8801,Pipeline_Completo!$D$2:$D$8801,$C4,Pipeline_Completo!$O$2:$O$8801,"Prospecting") -> 101409 | M4: =COUNTIFS(Pipeline_Completo!$D$2:$D$8801,$C4,Pipeline_Completo!$V$2:$V$8801,"Saudável")+COUNTIFS(Pipeline_Completo!$D$2:$D$8801,$C4,Pipeline_Completo!$V$2:$V$8801,"Esfriando")+COUNTIFS(Pipeline_Completo!$D$2:$D$8801,$C4,Pipeline_Completo!$V$2:$V$8801,"Última chance") -> 1 | N4: =SUMIFS(Pipeline_Completo!$S$2:$S$8801,Pipeline_Completo!$D$2:$D$8801,$C4,Pipeline_Completo!$V$2:$V$8801,"Saudável")+SUMIFS(Pipeline_Completo!$S$2:$S$8801,Pipeline_Completo!$D$2:$D$8801,$C4,Pipeline_Completo!$V$2:$V$8801,"Esfriando")+SUMIFS(Pipeline_Completo!$S$2:$S$8801,Pipeline_Completo!$D$2:$D$8801,$C4,Pipeline_Completo!$V$2:$V$8801,"Última chance") -> 55 | O4: =COUNTIFS(Pipeline_Completo!$D$2:$D$8801,$C4,Pipeline_Completo!$V$2:$V$8801,"Zumbi") -> 42 | P4: =SUMIFS(Pipeline_Completo!$S$2:$S$8801,Pipeline_Completo!$D$2:$D$8801,$C4,Pipeline_Completo!$V$2:$V$8801,"Zumbi") -> 48603 | Q4: =IFERROR(P4/(N4+P4),"") -> 0.99886966 | R4: =COUNTIFS(Pipeline_Completo!$D$2:$D$8801,$C4,Pipeline_Completo!$O$2:$O$8801,"Engaging",Pipeline_Completo!$E$2:$E$8801,"")+COUNTIFS(Pipeline_Completo!$D$2:$D$8801,$C4,Pipeline_Completo!$O$2:$O$8801,"Prospecting",Pipeline_Completo!$E$2:$E$8801,"") -> 69
A5: Central | B5: Dustin Brinkmann | C5: Lajuana Vencill | D5: =COUNTIFS(Pipeline_Completo!$D$2:$D$8801,$C5) -> 311 | E5: =COUNTIFS(Pipeline_Completo!$D$2:$D$8801,$C5,Pipeline_Completo!$O$2:$O$8801,"Won") -> 127 | F5: =COUNTIFS(Pipeline_Completo!$D$2:$D$8801,$C5,Pipeline_Completo!$O$2:$O$8801,"Lost") -> 104 | G5: =COUNTIFS(Pipeline_Completo!$D$2:$D$8801,$C5,Pipeline_Completo!$O$2:$O$8801,"Engaging") -> 40 | H5: =COUNTIFS(Pipeline_Completo!$D$2:$D$8801,$C5,Pipeline_Completo!$O$2:$O$8801,"Prospecting") -> 40 | I5: =IFERROR(E5/(E5+F5),"") -> 0.54978355 | J5: =SUMIFS(Pipeline_Completo!$R$2:$R$8801,Pipeline_Completo!$D$2:$D$8801,$C5,Pipeline_Completo!$O$2:$O$8801,"Won") -> 194632 | K5: =IFERROR(J5/E5,"") -> 1532.5354 | L5: =SUMIFS(Pipeline_Completo!$S$2:$S$8801,Pipeline_Completo!$D$2:$D$8801,$C5,Pipeline_Completo!$O$2:$O$8801,"Engaging")+SUMIFS(Pipeline_Completo!$S$2:$S$8801,Pipeline_Completo!$D$2:$D$8801,$C5,Pipeline_Completo!$O$2:$O$8801,"Prospecting") -> 116039 | M5: =COUNTIFS(Pipeline_Completo!$D$2:$D$8801,$C5,Pipeline_Completo!$V$2:$V$8801,"Saudável")+COUNTIFS(Pipeline_Completo!$D$2:$D$8801,$C5,Pipeline_Completo!$V$2:$V$8801,"Esfriando")+COUNTIFS(Pipeline_Completo!$D$2:$D$8801,$C5,Pipeline_Completo!$V$2:$V$8801,"Última chance") -> 1 | N5: =SUMIFS(Pipeline_Completo!$S$2:$S$8801,Pipeline_Completo!$D$2:$D$8801,$C5,Pipeline_Completo!$V$2:$V$8801,"Saudável")+SUMIFS(Pipeline_Completo!$S$2:$S$8801,Pipeline_Completo!$D$2:$D$8801,$C5,Pipeline_Completo!$V$2:$V$8801,"Esfriando")+SUMIFS(Pipeline_Completo!$S$2:$S$8801,Pipeline_Completo!$D$2:$D$8801,$C5,Pipeline_Completo!$V$2:$V$8801,"Última chance") -> 550 | O5: =COUNTIFS(Pipeline_Completo!$D$2:$D$8801,$C5,Pipeline_Completo!$V$2:$V$8801,"Zumbi") -> 39 | P5: =SUMIFS(Pipeline_Completo!$S$2:$S$8801,Pipeline_Completo!$D$2:$D$8801,$C5,Pipeline_Completo!$V$2:$V$8801,"Zumbi") -> 57968 | Q5: =IFERROR(P5/(N5+P5),"") -> 0.99060118 | R5: =COUNTIFS(Pipeline_Completo!$D$2:$D$8801,$C5,Pipeline_Completo!$O$2:$O$8801,"Engaging",Pipeline_Completo!$E$2:$E$8801,"")+COUNTIFS(Pipeline_Completo!$D$2:$D$8801,$C5,Pipeline_Completo!$O$2:$O$8801,"Prospecting",Pipeline_Completo!$E$2:$E$8801,"") -> 57
A6: Central | B6: Dustin Brinkmann | C6: Moses Frase | D6: =COUNTIFS(Pipeline_Completo!$D$2:$D$8801,$C6) -> 260 | E6: =COUNTIFS(Pipeline_Completo!$D$2:$D$8801,$C6,Pipeline_Completo!$O$2:$O$8801,"Won") -> 129 | F6: =COUNTIFS(Pipeline_Completo!$D$2:$D$8801,$C6,Pipeline_Completo!$O$2:$O$8801,"Lost") -> 66 | G6: =COUNTIFS(Pipeline_Completo!$D$2:$D$8801,$C6,Pipeline_Completo!$O$2:$O$8801,"Engaging") -> 34 | H6: =COUNTIFS(Pipeline_Completo!$D$2:$D$8801,$C6,Pipeline_Completo!$O$2:$O$8801,"Prospecting") -> 31 | I6: =IFERROR(E6/(E6+F6),"") -> 0.66153846 | J6: =SUMIFS(Pipeline_Completo!$R$2:$R$8801,Pipeline_Completo!$D$2:$D$8801,$C6,Pipeline_Completo!$O$2:$O$8801,"Won") -> 207182 | K6: =IFERROR(J6/E6,"") -> 1606.062 | L6: =SUMIFS(Pipeline_Completo!$S$2:$S$8801,Pipeline_Completo!$D$2:$D$8801,$C6,Pipeline_Completo!$O$2:$O$8801,"Engaging")+SUMIFS(Pipeline_Completo!$S$2:$S$8801,Pipeline_Completo!$D$2:$D$8801,$C6,Pipeline_Completo!$O$2:$O$8801,"Prospecting") -> 108161 | M6: =COUNTIFS(Pipeline_Completo!$D$2:$D$8801,$C6,Pipeline_Completo!$V$2:$V$8801,"Saudável")+COUNTIFS(Pipeline_Completo!$D$2:$D$8801,$C6,Pipeline_Completo!$V$2:$V$8801,"Esfriando")+COUNTIFS(Pipeline_Completo!$D$2:$D$8801,$C6,Pipeline_Completo!$V$2:$V$8801,"Última chance") -> 0 | N6: =SUMIFS(Pipeline_Completo!$S$2:$S$8801,Pipeline_Completo!$D$2:$D$8801,$C6,Pipeline_Completo!$V$2:$V$8801,"Saudável")+SUMIFS(Pipeline_Completo!$S$2:$S$8801,Pipeline_Completo!$D$2:$D$8801,$C6,Pipeline_Completo!$V$2:$V$8801,"Esfriando")+SUMIFS(Pipeline_Completo!$S$2:$S$8801,Pipeline_Completo!$D$2:$D$8801,$C6,Pipeline_Completo!$V$2:$V$8801,"Última chance") -> 0 | O6: =COUNTIFS(Pipeline_Completo!$D$2:$D$8801,$C6,Pipeline_Completo!$V$2:$V$8801,"Zumbi") -> 34 | P6: =SUMIFS(Pipeline_Completo!$S$2:$S$8801,Pipeline_Completo!$D$2:$D$8801,$C6,Pipeline_Completo!$V$2:$V$8801,"Zumbi") -> 50552 | Q6: =IFERROR(P6/(N6+P6),"") -> 1 | R6: =COUNTIFS(Pipeline_Completo!$D$2:$D$8801,$C6,Pipeline_Completo!$O$2:$O$8801,"Engaging",Pipeline_Completo!$E$2:$E$8801,"")+COUNTIFS(Pipeline_Completo!$D$2:$D$8801,$C6,Pipeline_Completo!$O$2:$O$8801,"Prospecting",Pipeline_Completo!$E$2:$E$8801,"") -> 44
A7: Central | B7: Dustin Brinkmann | C7: Subtotal Dustin Brinkmann | D7: =COUNTIFS(Pipeline_Completo!$C$2:$C$8801,$B7) -> 1583 | E7: =COUNTIFS(Pipeline_Completo!$C$2:$C$8801,$B7,Pipeline_Completo!$O$2:$O$8801,"Won") -> 747 | F7: =COUNTIFS(Pipeline_Completo!$C$2:$C$8801,$B7,Pipeline_Completo!$O$2:$O$8801,"Lost") -> 439 | G7: =COUNTIFS(Pipeline_Completo!$C$2:$C$8801,$B7,Pipeline_Completo!$O$2:$O$8801,"Engaging") -> 193 | H7: =COUNTIFS(Pipeline_Completo!$C$2:$C$8801,$B7,Pipeline_Completo!$O$2:$O$8801,"Prospecting") -> 204 | I7: =IFERROR(E7/(E7+F7),"") -> 0.62984823 | J7: =SUMIFS(Pipeline_Completo!$R$2:$R$8801,Pipeline_Completo!$C$2:$C$8801,$B7,Pipeline_Completo!$O$2:$O$8801,"Won") -> 1094363 | K7: =IFERROR(J7/E7,"") -> 1465.0107 | L7: =SUMIFS(Pipeline_Completo!$S$2:$S$8801,Pipeline_Completo!$C$2:$C$8801,$B7,Pipeline_Completo!$O$2:$O$8801,"Engaging")+SUMIFS(Pipeline_Completo!$S$2:$S$8801,Pipeline_Completo!$C$2:$C$8801,$B7,Pipeline_Completo!$O$2:$O$8801,"Prospecting") -> 585616 | M7: =COUNTIFS(Pipeline_Completo!$C$2:$C$8801,$B7,Pipeline_Completo!$V$2:$V$8801,"Saudável")+COUNTIFS(Pipeline_Completo!$C$2:$C$8801,$B7,Pipeline_Completo!$V$2:$V$8801,"Esfriando")+COUNTIFS(Pipeline_Completo!$C$2:$C$8801,$B7,Pipeline_Completo!$V$2:$V$8801,"Última chance") -> 3 | N7: =SUMIFS(Pipeline_Completo!$S$2:$S$8801,Pipeline_Completo!$C$2:$C$8801,$B7,Pipeline_Completo!$V$2:$V$8801,"Saudável")+SUMIFS(Pipeline_Completo!$S$2:$S$8801,Pipeline_Completo!$C$2:$C$8801,$B7,Pipeline_Completo!$V$2:$V$8801,"Esfriando")+SUMIFS(Pipeline_Completo!$S$2:$S$8801,Pipeline_Completo!$C$2:$C$8801,$B7,Pipeline_Completo!$V$2:$V$8801,"Última chance") -> 660 | O7: =COUNTIFS(Pipeline_Completo!$C$2:$C$8801,$B7,Pipeline_Completo!$V$2:$V$8801,"Zumbi") -> 190 | P7: =SUMIFS(Pipeline_Completo!$S$2:$S$8801,Pipeline_Completo!$C$2:$C$8801,$B7,Pipeline_Completo!$V$2:$V$8801,"Zumbi") -> 282047 | Q7: =IFERROR(P7/(N7+P7),"") -> 0.99766543 | R7: =COUNTIFS(Pipeline_Completo!$C$2:$C$8801,$B7,Pipeline_Completo!$O$2:$O$8801,"Engaging",Pipeline_Completo!$E$2:$E$8801,"")+COUNTIFS(Pipeline_Completo!$C$2:$C$8801,$B7,Pipeline_Completo!$O$2:$O$8801,"Prospecting",Pipeline_Completo!$E$2:$E$8801,"") -> 272
A8: Central | B8: Melvin Marxen | C8: Jonathan Berthelot | D8: =COUNTIFS(Pipeline_Completo!$D$2:$D$8801,$C8) -> 345 | E8: =COUNTIFS(Pipeline_Completo!$D$2:$D$8801,$C8,Pipeline_Completo!$O$2:$O$8801,"Won") -> 171 | F8: =COUNTIFS(Pipeline_Completo!$D$2:$D$8801,$C8,Pipeline_Completo!$O$2:$O$8801,"Lost") -> 93 | G8: =COUNTIFS(Pipeline_Completo!$D$2:$D$8801,$C8,Pipeline_Completo!$O$2:$O$8801,"Engaging") -> 33 | H8: =COUNTIFS(Pipeline_Completo!$D$2:$D$8801,$C8,Pipeline_Completo!$O$2:$O$8801,"Prospecting") -> 48 | I8: =IFERROR(E8/(E8+F8),"") -> 0.64772727 | J8: =SUMIFS(Pipeline_Completo!$R$2:$R$8801,Pipeline_Completo!$D$2:$D$8801,$C8,Pipeline_Completo!$O$2:$O$8801,"Won") -> 284886 | K8: =IFERROR(J8/E8,"") -> 1666 | L8: =SUMIFS(Pipeline_Completo!$S$2:$S$8801,Pipeline_Completo!$D$2:$D$8801,$C8,Pipeline_Completo!$O$2:$O$8801,"Engaging")+SUMIFS(Pipeline_Completo!$S$2:$S$8801,Pipeline_Completo!$D$2:$D$8801,$C8,Pipeline_Completo!$O$2:$O$8801,"Prospecting") -> 127420 | M8: =COUNTIFS(Pipeline_Completo!$D$2:$D$8801,$C8,Pipeline_Completo!$V$2:$V$8801,"Saudável")+COUNTIFS(Pipeline_Completo!$D$2:$D$8801,$C8,Pipeline_Completo!$V$2:$V$8801,"Esfriando")+COUNTIFS(Pipeline_Completo!$D$2:$D$8801,$C8,Pipeline_Completo!$V$2:$V$8801,"Última chance") -> 0 | N8: =SUMIFS(Pipeline_Completo!$S$2:$S$8801,Pipeline_Completo!$D$2:$D$8801,$C8,Pipeline_Completo!$V$2:$V$8801,"Saudável")+SUMIFS(Pipeline_Completo!$S$2:$S$8801,Pipeline_Completo!$D$2:$D$8801,$C8,Pipeline_Completo!$V$2:$V$8801,"Esfriando")+SUMIFS(Pipeline_Completo!$S$2:$S$8801,Pipeline_Completo!$D$2:$D$8801,$C8,Pipeline_Completo!$V$2:$V$8801,"Última chance") -> 0 | O8: =COUNTIFS(Pipeline_Completo!$D$2:$D$8801,$C8,Pipeline_Completo!$V$2:$V$8801,"Zumbi") -> 33 | P8: =SUMIFS(Pipeline_Completo!$S$2:$S$8801,Pipeline_Completo!$D$2:$D$8801,$C8,Pipeline_Completo!$V$2:$V$8801,"Zumbi") -> 39704 | Q8: =IFERROR(P8/(N8+P8),"") -> 1 | R8: =COUNTIFS(Pipeline_Completo!$D$2:$D$8801,$C8,Pipeline_Completo!$O$2:$O$8801,"Engaging",Pipeline_Completo!$E$2:$E$8801,"")+COUNTIFS(Pipeline_Completo!$D$2:$D$8801,$C8,Pipeline_Completo!$O$2:$O$8801,"Prospecting",Pipeline_Completo!$E$2:$E$8801,"") -> 58
A9: Central | B9: Melvin Marxen | C9: Marty Freudenburg | D9: =COUNTIFS(Pipeline_Completo!$D$2:$D$8801,$C9) -> 281 | E9: =COUNTIFS(Pipeline_Completo!$D$2:$D$8801,$C9,Pipeline_Completo!$O$2:$O$8801,"Won") -> 122 | F9: =COUNTIFS(Pipeline_Completo!$D$2:$D$8801,$C9,Pipeline_Completo!$O$2:$O$8801,"Lost") -> 72 | G9: =COUNTIFS(Pipeline_Completo!$D$2:$D$8801,$C9,Pipeline_Completo!$O$2:$O$8801,"Engaging") -> 33 | H9: =COUNTIFS(Pipeline_Completo!$D$2:$D$8801,$C9,Pipeline_Completo!$O$2:$O$8801,"Prospecting") -> 54 | I9: =IFERROR(E9/(E9+F9),"") -> 0.62886598 | J9: =SUMIFS(Pipeline_Completo!$R$2:$R$8801,Pipeline_Completo!$D$2:$D$8801,$C9,Pipeline_Completo!$O$2:$O$8801,"Won") -> 291195 | K9: =IFERROR(J9/E9,"") -> 2386.8443 | L9: =SUMIFS(Pipeline_Completo!$S$2:$S$8801,Pipeline_Completo!$D$2:$D$8801,$C9,Pipeline_Completo!$O$2:$O$8801,"Engaging")+SUMIFS(Pipeline_Completo!$S$2:$S$8801,Pipeline_Completo!$D$2:$D$8801,$C9,Pipeline_Completo!$O$2:$O$8801,"Prospecting") -> 229445 | M9: =COUNTIFS(Pipeline_Completo!$D$2:$D$8801,$C9,Pipeline_Completo!$V$2:$V$8801,"Saudável")+COUNTIFS(Pipeline_Completo!$D$2:$D$8801,$C9,Pipeline_Completo!$V$2:$V$8801,"Esfriando")+COUNTIFS(Pipeline_Completo!$D$2:$D$8801,$C9,Pipeline_Completo!$V$2:$V$8801,"Última chance") -> 0 | N9: =SUMIFS(Pipeline_Completo!$S$2:$S$8801,Pipeline_Completo!$D$2:$D$8801,$C9,Pipeline_Completo!$V$2:$V$8801,"Saudável")+SUMIFS(Pipeline_Completo!$S$2:$S$8801,Pipeline_Completo!$D$2:$D$8801,$C9,Pipeline_Completo!$V$2:$V$8801,"Esfriando")+SUMIFS(Pipeline_Completo!$S$2:$S$8801,Pipeline_Completo!$D$2:$D$8801,$C9,Pipeline_Completo!$V$2:$V$8801,"Última chance") -> 0 | O9: =COUNTIFS(Pipeline_Completo!$D$2:$D$8801,$C9,Pipeline_Completo!$V$2:$V$8801,"Zumbi") -> 33 | P9: =SUMIFS(Pipeline_Completo!$S$2:$S$8801,Pipeline_Completo!$D$2:$D$8801,$C9,Pipeline_Completo!$V$2:$V$8801,"Zumbi") -> 108803 | Q9: =IFERROR(P9/(N9+P9),"") -> 1 | R9: =COUNTIFS(Pipeline_Completo!$D$2:$D$8801,$C9,Pipeline_Completo!$O$2:$O$8801,"Engaging",Pipeline_Completo!$E$2:$E$8801,"")+COUNTIFS(Pipeline_Completo!$D$2:$D$8801,$C9,Pipeline_Completo!$O$2:$O$8801,"Prospecting",Pipeline_Completo!$E$2:$E$8801,"") -> 53
A10: Central | B10: Melvin Marxen | C10: Gladys Colclough | D10: =COUNTIFS(Pipeline_Completo!$D$2:$D$8801,$C10) -> 317 | E10: =COUNTIFS(Pipeline_Completo!$D$2:$D$8801,$C10,Pipeline_Completo!$O$2:$O$8801,"Won") -> 135 | F10: =COUNTIFS(Pipeline_Completo!$D$2:$D$8801,$C10,Pipeline_Completo!$O$2:$O$8801,"Lost") -> 97 | G10: =COUNTIFS(Pipeline_Completo!$D$2:$D$8801,$C10,Pipeline_Completo!$O$2:$O$8801,"Engaging") -> 36 | H10: =COUNTIFS(Pipeline_Completo!$D$2:$D$8801,$C10,Pipeline_Completo!$O$2:$O$8801,"Prospecting") -> 49 | I10: =IFERROR(E10/(E10+F10),"") -> 0.58189655 | J10: =SUMIFS(Pipeline_Completo!$R$2:$R$8801,Pipeline_Completo!$D$2:$D$8801,$C10,Pipeline_Completo!$O$2:$O$8801,"Won") -> 345674 | K10: =IFERROR(J10/E10,"") -> 2560.5481 | L10: =SUMIFS(Pipeline_Completo!$S$2:$S$8801,Pipeline_Completo!$D$2:$D$8801,$C10,Pipeline_Completo!$O$2:$O$8801,"Engaging")+SUMIFS(Pipeline_Completo!$S$2:$S$8801,Pipeline_Completo!$D$2:$D$8801,$C10,Pipeline_Completo!$O$2:$O$8801,"Prospecting") -> 192142 | M10: =COUNTIFS(Pipeline_Completo!$D$2:$D$8801,$C10,Pipeline_Completo!$V$2:$V$8801,"Saudável")+COUNTIFS(Pipeline_Completo!$D$2:$D$8801,$C10,Pipeline_Completo!$V$2:$V$8801,"Esfriando")+COUNTIFS(Pipeline_Completo!$D$2:$D$8801,$C10,Pipeline_Completo!$V$2:$V$8801,"Última chance") -> 0 | N10: =SUMIFS(Pipeline_Completo!$S$2:$S$8801,Pipeline_Completo!$D$2:$D$8801,$C10,Pipeline_Completo!$V$2:$V$8801,"Saudável")+SUMIFS(Pipeline_Completo!$S$2:$S$8801,Pipeline_Completo!$D$2:$D$8801,$C10,Pipeline_Completo!$V$2:$V$8801,"Esfriando")+SUMIFS(Pipeline_Completo!$S$2:$S$8801,Pipeline_Completo!$D$2:$D$8801,$C10,Pipeline_Completo!$V$2:$V$8801,"Última chance") -> 0 | O10: =COUNTIFS(Pipeline_Completo!$D$2:$D$8801,$C10,Pipeline_Completo!$V$2:$V$8801,"Zumbi") -> 36 | P10: =SUMIFS(Pipeline_Completo!$S$2:$S$8801,Pipeline_Completo!$D$2:$D$8801,$C10,Pipeline_Completo!$V$2:$V$8801,"Zumbi") -> 62513 | Q10: =IFERROR(P10/(N10+P10),"") -> 1 | R10: =COUNTIFS(Pipeline_Completo!$D$2:$D$8801,$C10,Pipeline_Completo!$O$2:$O$8801,"Engaging",Pipeline_Completo!$E$2:$E$8801,"")+COUNTIFS(Pipeline_Completo!$D$2:$D$8801,$C10,Pipeline_Completo!$O$2:$O$8801,"Prospecting",Pipeline_Completo!$E$2:$E$8801,"") -> 55
A11: Central | B11: Melvin Marxen | C11: Niesha Huffines | D11: =COUNTIFS(Pipeline_Completo!$D$2:$D$8801,$C11) -> 239 | E11: =COUNTIFS(Pipeline_Completo!$D$2:$D$8801,$C11,Pipeline_Completo!$O$2:$O$8801,"Won") -> 105 | F11: =COUNTIFS(Pipeline_Completo!$D$2:$D$8801,$C11,Pipeline_Completo!$O$2:$O$8801,"Lost") -> 70 | G11: =COUNTIFS(Pipeline_Completo!$D$2:$D$8801,$C11,Pipeline_Completo!$O$2:$O$8801,"Engaging") -> 30 | H11: =COUNTIFS(Pipeline_Completo!$D$2:$D$8801,$C11,Pipeline_Completo!$O$2:$O$8801,"Prospecting") -> 34 | I11: =IFERROR(E11/(E11+F11),"") -> 0.6 | J11: =SUMIFS(Pipeline_Completo!$R$2:$R$8801,Pipeline_Completo!$D$2:$D$8801,$C11,Pipeline_Completo!$O$2:$O$8801,"Won") -> 176961 | K11: =IFERROR(J11/E11,"") -> 1685.3429 | L11: =SUMIFS(Pipeline_Completo!$S$2:$S$8801,Pipeline_Completo!$D$2:$D$8801,$C11,Pipeline_Completo!$O$2:$O$8801,"Engaging")+SUMIFS(Pipeline_Completo!$S$2:$S$8801,Pipeline_Completo!$D$2:$D$8801,$C11,Pipeline_Completo!$O$2:$O$8801,"Prospecting") -> 107745 | M11: =COUNTIFS(Pipeline_Completo!$D$2:$D$8801,$C11,Pipeline_Completo!$V$2:$V$8801,"Saudável")+COUNTIFS(Pipeline_Completo!$D$2:$D$8801,$C11,Pipeline_Completo!$V$2:$V$8801,"Esfriando")+COUNTIFS(Pipeline_Completo!$D$2:$D$8801,$C11,Pipeline_Completo!$V$2:$V$8801,"Última chance") -> 2 | N11: =SUMIFS(Pipeline_Completo!$S$2:$S$8801,Pipeline_Completo!$D$2:$D$8801,$C11,Pipeline_Completo!$V$2:$V$8801,"Saudável")+SUMIFS(Pipeline_Completo!$S$2:$S$8801,Pipeline_Completo!$D$2:$D$8801,$C11,Pipeline_Completo!$V$2:$V$8801,"Esfriando")+SUMIFS(Pipeline_Completo!$S$2:$S$8801,Pipeline_Completo!$D$2:$D$8801,$C11,Pipeline_Completo!$V$2:$V$8801,"Última chance") -> 5917 | O11: =COUNTIFS(Pipeline_Completo!$D$2:$D$8801,$C11,Pipeline_Completo!$V$2:$V$8801,"Zumbi") -> 28 | P11: =SUMIFS(Pipeline_Completo!$S$2:$S$8801,Pipeline_Completo!$D$2:$D$8801,$C11,Pipeline_Completo!$V$2:$V$8801,"Zumbi") -> 51012 | Q11: =IFERROR(P11/(N11+P11),"") -> 0.89606352 | R11: =COUNTIFS(Pipeline_Completo!$D$2:$D$8801,$C11,Pipeline_Completo!$O$2:$O$8801,"Engaging",Pipeline_Completo!$E$2:$E$8801,"")+COUNTIFS(Pipeline_Completo!$D$2:$D$8801,$C11,Pipeline_Completo!$O$2:$O$8801,"Prospecting",Pipeline_Completo!$E$2:$E$8801,"") -> 39
A12: Central | B12: Melvin Marxen | C12: Darcel Schlecht | D12: =COUNTIFS(Pipeline_Completo!$D$2:$D$8801,$C12) -> 747 | E12: =COUNTIFS(Pipeline_Completo!$D$2:$D$8801,$C12,Pipeline_Completo!$O$2:$O$8801,"Won") -> 349 | F12: =COUNTIFS(Pipeline_Completo!$D$2:$D$8801,$C12,Pipeline_Completo!$O$2:$O$8801,"Lost") -> 204 | G12: =COUNTIFS(Pipeline_Completo!$D$2:$D$8801,$C12,Pipeline_Completo!$O$2:$O$8801,"Engaging") -> 83 | H12: =COUNTIFS(Pipeline_Completo!$D$2:$D$8801,$C12,Pipeline_Completo!$O$2:$O$8801,"Prospecting") -> 111 | I12: =IFERROR(E12/(E12+F12),"") -> 0.63110307 | J12: =SUMIFS(Pipeline_Completo!$R$2:$R$8801,Pipeline_Completo!$D$2:$D$8801,$C12,Pipeline_Completo!$O$2:$O$8801,"Won") -> 1153214 | K12: =IFERROR(J12/E12,"") -> 3304.3381 | L12: =SUMIFS(Pipeline_Completo!$S$2:$S$8801,Pipeline_Completo!$D$2:$D$8801,$C12,Pipeline_Completo!$O$2:$O$8801,"Engaging")+SUMIFS(Pipeline_Completo!$S$2:$S$8801,Pipeline_Completo!$D$2:$D$8801,$C12,Pipeline_Completo!$O$2:$O$8801,"Prospecting") -> 656040 | M12: =COUNTIFS(Pipeline_Completo!$D$2:$D$8801,$C12,Pipeline_Completo!$V$2:$V$8801,"Saudável")+COUNTIFS(Pipeline_Completo!$D$2:$D$8801,$C12,Pipeline_Completo!$V$2:$V$8801,"Esfriando")+COUNTIFS(Pipeline_Completo!$D$2:$D$8801,$C12,Pipeline_Completo!$V$2:$V$8801,"Última chance") -> 0 | N12: =SUMIFS(Pipeline_Completo!$S$2:$S$8801,Pipeline_Completo!$D$2:$D$8801,$C12,Pipeline_Completo!$V$2:$V$8801,"Saudável")+SUMIFS(Pipeline_Completo!$S$2:$S$8801,Pipeline_Completo!$D$2:$D$8801,$C12,Pipeline_Completo!$V$2:$V$8801,"Esfriando")+SUMIFS(Pipeline_Completo!$S$2:$S$8801,Pipeline_Completo!$D$2:$D$8801,$C12,Pipeline_Completo!$V$2:$V$8801,"Última chance") -> 0 | O12: =COUNTIFS(Pipeline_Completo!$D$2:$D$8801,$C12,Pipeline_Completo!$V$2:$V$8801,"Zumbi") -> 83 | P12: =SUMIFS(Pipeline_Completo!$S$2:$S$8801,Pipeline_Completo!$D$2:$D$8801,$C12,Pipeline_Completo!$V$2:$V$8801,"Zumbi") -> 273766 | Q12: =IFERROR(P12/(N12+P12),"") -> 1 | R12: =COUNTIFS(Pipeline_Completo!$D$2:$D$8801,$C12,Pipeline_Completo!$O$2:$O$8801,"Engaging",Pipeline_Completo!$E$2:$E$8801,"")+COUNTIFS(Pipeline_Completo!$D$2:$D$8801,$C12,Pipeline_Completo!$O$2:$O$8801,"Prospecting",Pipeline_Completo!$E$2:$E$8801,"") -> 134
A13: Central | B13: Melvin Marxen | C13: Mei-Mei Johns | D13: =COUNTIFS(Pipeline_Completo!$D$2:$D$8801,$C13) -> 0 | E13: =COUNTIFS(Pipeline_Completo!$D$2:$D$8801,$C13,Pipeline_Completo!$O$2:$O$8801,"Won") -> 0 | F13: =COUNTIFS(Pipeline_Completo!$D$2:$D$8801,$C13,Pipeline_Completo!$O$2:$O$8801,"Lost") -> 0 | G13: =COUNTIFS(Pipeline_Completo!$D$2:$D$8801,$C13,Pipeline_Completo!$O$2:$O$8801,"Engaging") -> 0 | H13: =COUNTIFS(Pipeline_Completo!$D$2:$D$8801,$C13,Pipeline_Completo!$O$2:$O$8801,"Prospecting") -> 0 | I13: =IFERROR(E13/(E13+F13),"") | J13: =SUMIFS(Pipeline_Completo!$R$2:$R$8801,Pipeline_Completo!$D$2:$D$8801,$C13,Pipeline_Completo!$O$2:$O$8801,"Won") -> 0 | K13: =IFERROR(J13/E13,"") | L13: =SUMIFS(Pipeline_Completo!$S$2:$S$8801,Pipeline_Completo!$D$2:$D$8801,$C13,Pipeline_Completo!$O$2:$O$8801,"Engaging")+SUMIFS(Pipeline_Completo!$S$2:$S$8801,Pipeline_Completo!$D$2:$D$8801,$C13,Pipeline_Completo!$O$2:$O$8801,"Prospecting") -> 0 | M13: =COUNTIFS(Pipeline_Completo!$D$2:$D$8801,$C13,Pipeline_Completo!$V$2:$V$8801,"Saudável")+COUNTIFS(Pipeline_Completo!$D$2:$D$8801,$C13,Pipeline_Completo!$V$2:$V$8801,"Esfriando")+COUNTIFS(Pipeline_Completo!$D$2:$D$8801,$C13,Pipeline_Completo!$V$2:$V$8801,"Última chance") -> 0 | N13: =SUMIFS(Pipeline_Completo!$S$2:$S$8801,Pipeline_Completo!$D$2:$D$8801,$C13,Pipeline_Completo!$V$2:$V$8801,"Saudável")+SUMIFS(Pipeline_Completo!$S$2:$S$8801,Pipeline_Completo!$D$2:$D$8801,$C13,Pipeline_Completo!$V$2:$V$8801,"Esfriando")+SUMIFS(Pipeline_Completo!$S$2:$S$8801,Pipeline_Completo!$D$2:$D$8801,$C13,Pipeline_Completo!$V$2:$V$8801,"Última chance") -> 0 | O13: =COUNTIFS(Pipeline_Completo!$D$2:$D$8801,$C13,Pipeline_Completo!$V$2:$V$8801,"Zumbi") -> 0 | P13: =SUMIFS(Pipeline_Completo!$S$2:$S$8801,Pipeline_Completo!$D$2:$D$8801,$C13,Pipeline_Completo!$V$2:$V$8801,"Zumbi") -> 0 | Q13: =IFERROR(P13/(N13+P13),"") | R13: =COUNTIFS(Pipeline_Completo!$D$2:$D$8801,$C13,Pipeline_Completo!$O$2:$O$8801,"Engaging",Pipeline_Completo!$E$2:$E$8801,"")+COUNTIFS(Pipeline_Completo!$D$2:$D$8801,$C13,Pipeline_Completo!$O$2:$O$8801,"Prospecting",Pipeline_Completo!$E$2:$E$8801,"") -> 0
A14: Central | B14: Melvin Marxen | C14: Subtotal Melvin Marxen | D14: =COUNTIFS(Pipeline_Completo!$C$2:$C$8801,$B14) -> 1929 | E14: =COUNTIFS(Pipeline_Completo!$C$2:$C$8801,$B14,Pipeline_Completo!$O$2:$O$8801,"Won") -> 882 | F14: =COUNTIFS(Pipeline_Completo!$C$2:$C$8801,$B14,Pipeline_Completo!$O$2:$O$8801,"Lost") -> 536 | G14: =COUNTIFS(Pipeline_Completo!$C$2:$C$8801,$B14,Pipeline_Completo!$O$2:$O$8801,"Engaging") -> 215 | H14: =COUNTIFS(Pipeline_Completo!$C$2:$C$8801,$B14,Pipeline_Completo!$O$2:$O$8801,"Prospecting") -> 296 | I14: =IFERROR(E14/(E14+F14),"") -> 0.62200282 | J14: =SUMIFS(Pipeline_Completo!$R$2:$R$8801,Pipeline_Completo!$C$2:$C$8801,$B14,Pipeline_Completo!$O$2:$O$8801,"Won") -> 2251930 | K14: =IFERROR(J14/E14,"") -> 2553.2086 | L14: =SUMIFS(Pipeline_Completo!$S$2:$S$8801,Pipeline_Completo!$C$2:$C$8801,$B14,Pipeline_Completo!$O$2:$O$8801,"Engaging")+SUMIFS(Pipeline_Completo!$S$2:$S$8801,Pipeline_Completo!$C$2:$C$8801,$B14,Pipeline_Completo!$O$2:$O$8801,"Prospecting") -> 1312792 | M14: =COUNTIFS(Pipeline_Completo!$C$2:$C$8801,$B14,Pipeline_Completo!$V$2:$V$8801,"Saudável")+COUNTIFS(Pipeline_Completo!$C$2:$C$8801,$B14,Pipeline_Completo!$V$2:$V$8801,"Esfriando")+COUNTIFS(Pipeline_Completo!$C$2:$C$8801,$B14,Pipeline_Completo!$V$2:$V$8801,"Última chance") -> 2 | N14: =SUMIFS(Pipeline_Completo!$S$2:$S$8801,Pipeline_Completo!$C$2:$C$8801,$B14,Pipeline_Completo!$V$2:$V$8801,"Saudável")+SUMIFS(Pipeline_Completo!$S$2:$S$8801,Pipeline_Completo!$C$2:$C$8801,$B14,Pipeline_Completo!$V$2:$V$8801,"Esfriando")+SUMIFS(Pipeline_Completo!$S$2:$S$8801,Pipeline_Completo!$C$2:$C$8801,$B14,Pipeline_Completo!$V$2:$V$8801,"Última chance") -> 5917 | O14: =COUNTIFS(Pipeline_Completo!$C$2:$C$8801,$B14,Pipeline_Completo!$V$2:$V$8801,"Zumbi") -> 213 | P14: =SUMIFS(Pipeline_Completo!$S$2:$S$8801,Pipeline_Completo!$C$2:$C$8801,$B14,Pipeline_Completo!$V$2:$V$8801,"Zumbi") -> 535798 | Q14: =IFERROR(P14/(N14+P14),"") -> 0.98907728 | R14: =COUNTIFS(Pipeline_Completo!$C$2:$C$8801,$B14,Pipeline_Completo!$O$2:$O$8801,"Engaging",Pipeline_Completo!$E$2:$E$8801,"")+COUNTIFS(Pipeline_Completo!$C$2:$C$8801,$B14,Pipeline_Completo!$O$2:$O$8801,"Prospecting",Pipeline_Completo!$E$2:$E$8801,"") -> 339
A15: Central | C15: TOTAL escritório Central | D15: =COUNTIFS(Pipeline_Completo!$B$2:$B$8801,$A15) -> 3512 | E15: =COUNTIFS(Pipeline_Completo!$B$2:$B$8801,$A15,Pipeline_Completo!$O$2:$O$8801,"Won") -> 1629 | F15: =COUNTIFS(Pipeline_Completo!$B$2:$B$8801,$A15,Pipeline_Completo!$O$2:$O$8801,"Lost") -> 975 | G15: =COUNTIFS(Pipeline_Completo!$B$2:$B$8801,$A15,Pipeline_Completo!$O$2:$O$8801,"Engaging") -> 408 | H15: =COUNTIFS(Pipeline_Completo!$B$2:$B$8801,$A15,Pipeline_Completo!$O$2:$O$8801,"Prospecting") -> 500 | I15: =IFERROR(E15/(E15+F15),"") -> 0.62557604 | J15: =SUMIFS(Pipeline_Completo!$R$2:$R$8801,Pipeline_Completo!$B$2:$B$8801,$A15,Pipeline_Completo!$O$2:$O$8801,"Won") -> 3346293 | K15: =IFERROR(J15/E15,"") -> 2054.2007 | L15: =SUMIFS(Pipeline_Completo!$S$2:$S$8801,Pipeline_Completo!$B$2:$B$8801,$A15,Pipeline_Completo!$O$2:$O$8801,"Engaging")+SUMIFS(Pipeline_Completo!$S$2:$S$8801,Pipeline_Completo!$B$2:$B$8801,$A15,Pipeline_Completo!$O$2:$O$8801,"Prospecting") -> 1898408 | M15: =COUNTIFS(Pipeline_Completo!$B$2:$B$8801,$A15,Pipeline_Completo!$V$2:$V$8801,"Saudável")+COUNTIFS(Pipeline_Completo!$B$2:$B$8801,$A15,Pipeline_Completo!$V$2:$V$8801,"Esfriando")+COUNTIFS(Pipeline_Completo!$B$2:$B$8801,$A15,Pipeline_Completo!$V$2:$V$8801,"Última chance") -> 5 | N15: =SUMIFS(Pipeline_Completo!$S$2:$S$8801,Pipeline_Completo!$B$2:$B$8801,$A15,Pipeline_Completo!$V$2:$V$8801,"Saudável")+SUMIFS(Pipeline_Completo!$S$2:$S$8801,Pipeline_Completo!$B$2:$B$8801,$A15,Pipeline_Completo!$V$2:$V$8801,"Esfriando")+SUMIFS(Pipeline_Completo!$S$2:$S$8801,Pipeline_Completo!$B$2:$B$8801,$A15,Pipeline_Completo!$V$2:$V$8801,"Última chance") -> 6577 | O15: =COUNTIFS(Pipeline_Completo!$B$2:$B$8801,$A15,Pipeline_Completo!$V$2:$V$8801,"Zumbi") -> 403 | P15: =SUMIFS(Pipeline_Completo!$S$2:$S$8801,Pipeline_Completo!$B$2:$B$8801,$A15,Pipeline_Completo!$V$2:$V$8801,"Zumbi") -> 817845 | Q15: =IFERROR(P15/(N15+P15),"") -> 0.99202229 | R15: =COUNTIFS(Pipeline_Completo!$B$2:$B$8801,$A15,Pipeline_Completo!$O$2:$O$8801,"Engaging",Pipeline_Completo!$E$2:$E$8801,"")+COUNTIFS(Pipeline_Completo!$B$2:$B$8801,$A15,Pipeline_Completo!$O$2:$O$8801,"Prospecting",Pipeline_Completo!$E$2:$E$8801,"") -> 611
A17: East | B17: Cara Losch | C17: Violet Mclelland | D17: =COUNTIFS(Pipeline_Completo!$D$2:$D$8801,$C17) -> 261 | E17: =COUNTIFS(Pipeline_Completo!$D$2:$D$8801,$C17,Pipeline_Completo!$O$2:$O$8801,"Won") -> 122 | F17: =COUNTIFS(Pipeline_Completo!$D$2:$D$8801,$C17,Pipeline_Completo!$O$2:$O$8801,"Lost") -> 71 | G17: =COUNTIFS(Pipeline_Completo!$D$2:$D$8801,$C17,Pipeline_Completo!$O$2:$O$8801,"Engaging") -> 68 | H17: =COUNTIFS(Pipeline_Completo!$D$2:$D$8801,$C17,Pipeline_Completo!$O$2:$O$8801,"Prospecting") -> 0 | I17: =IFERROR(E17/(E17+F17),"") -> 0.63212435 | J17: =SUMIFS(Pipeline_Completo!$R$2:$R$8801,Pipeline_Completo!$D$2:$D$8801,$C17,Pipeline_Completo!$O$2:$O$8801,"Won") -> 123431 | K17: =IFERROR(J17/E17,"") -> 1011.7295 | L17: =SUMIFS(Pipeline_Completo!$S$2:$S$8801,Pipeline_Completo!$D$2:$D$8801,$C17,Pipeline_Completo!$O$2:$O$8801,"Engaging")+SUMIFS(Pipeline_Completo!$S$2:$S$8801,Pipeline_Completo!$D$2:$D$8801,$C17,Pipeline_Completo!$O$2:$O$8801,"Prospecting") -> 80150 | M17: =COUNTIFS(Pipeline_Completo!$D$2:$D$8801,$C17,Pipeline_Completo!$V$2:$V$8801,"Saudável")+COUNTIFS(Pipeline_Completo!$D$2:$D$8801,$C17,Pipeline_Completo!$V$2:$V$8801,"Esfriando")+COUNTIFS(Pipeline_Completo!$D$2:$D$8801,$C17,Pipeline_Completo!$V$2:$V$8801,"Última chance") -> 17 | N17: =SUMIFS(Pipeline_Completo!$S$2:$S$8801,Pipeline_Completo!$D$2:$D$8801,$C17,Pipeline_Completo!$V$2:$V$8801,"Saudável")+SUMIFS(Pipeline_Completo!$S$2:$S$8801,Pipeline_Completo!$D$2:$D$8801,$C17,Pipeline_Completo!$V$2:$V$8801,"Esfriando")+SUMIFS(Pipeline_Completo!$S$2:$S$8801,Pipeline_Completo!$D$2:$D$8801,$C17,Pipeline_Completo!$V$2:$V$8801,"Última chance") -> 12606 | O17: =COUNTIFS(Pipeline_Completo!$D$2:$D$8801,$C17,Pipeline_Completo!$V$2:$V$8801,"Zumbi") -> 51 | P17: =SUMIFS(Pipeline_Completo!$S$2:$S$8801,Pipeline_Completo!$D$2:$D$8801,$C17,Pipeline_Completo!$V$2:$V$8801,"Zumbi") -> 67544 | Q17: =IFERROR(P17/(N17+P17),"") -> 0.8427199 | R17: =COUNTIFS(Pipeline_Completo!$D$2:$D$8801,$C17,Pipeline_Completo!$O$2:$O$8801,"Engaging",Pipeline_Completo!$E$2:$E$8801,"")+COUNTIFS(Pipeline_Completo!$D$2:$D$8801,$C17,Pipeline_Completo!$O$2:$O$8801,"Prospecting",Pipeline_Completo!$E$2:$E$8801,"") -> 48
A18: East | B18: Cara Losch | C18: Corliss Cosme | D18: =COUNTIFS(Pipeline_Completo!$D$2:$D$8801,$C18) -> 310 | E18: =COUNTIFS(Pipeline_Completo!$D$2:$D$8801,$C18,Pipeline_Completo!$O$2:$O$8801,"Won") -> 150 | F18: =COUNTIFS(Pipeline_Completo!$D$2:$D$8801,$C18,Pipeline_Completo!$O$2:$O$8801,"Lost") -> 79 | G18: =COUNTIFS(Pipeline_Completo!$D$2:$D$8801,$C18,Pipeline_Completo!$O$2:$O$8801,"Engaging") -> 81 | H18: =COUNTIFS(Pipeline_Completo!$D$2:$D$8801,$C18,Pipeline_Completo!$O$2:$O$8801,"Prospecting") -> 0 | I18: =IFERROR(E18/(E18+F18),"") -> 0.65502183 | J18: =SUMIFS(Pipeline_Completo!$R$2:$R$8801,Pipeline_Completo!$D$2:$D$8801,$C18,Pipeline_Completo!$O$2:$O$8801,"Won") -> 421036 | K18: =IFERROR(J18/E18,"") -> 2806.9067 | L18: =SUMIFS(Pipeline_Completo!$S$2:$S$8801,Pipeline_Completo!$D$2:$D$8801,$C18,Pipeline_Completo!$O$2:$O$8801,"Engaging")+SUMIFS(Pipeline_Completo!$S$2:$S$8801,Pipeline_Completo!$D$2:$D$8801,$C18,Pipeline_Completo!$O$2:$O$8801,"Prospecting") -> 216840 | M18: =COUNTIFS(Pipeline_Completo!$D$2:$D$8801,$C18,Pipeline_Completo!$V$2:$V$8801,"Saudável")+COUNTIFS(Pipeline_Completo!$D$2:$D$8801,$C18,Pipeline_Completo!$V$2:$V$8801,"Esfriando")+COUNTIFS(Pipeline_Completo!$D$2:$D$8801,$C18,Pipeline_Completo!$V$2:$V$8801,"Última chance") -> 18 | N18: =SUMIFS(Pipeline_Completo!$S$2:$S$8801,Pipeline_Completo!$D$2:$D$8801,$C18,Pipeline_Completo!$V$2:$V$8801,"Saudável")+SUMIFS(Pipeline_Completo!$S$2:$S$8801,Pipeline_Completo!$D$2:$D$8801,$C18,Pipeline_Completo!$V$2:$V$8801,"Esfriando")+SUMIFS(Pipeline_Completo!$S$2:$S$8801,Pipeline_Completo!$D$2:$D$8801,$C18,Pipeline_Completo!$V$2:$V$8801,"Última chance") -> 56886 | O18: =COUNTIFS(Pipeline_Completo!$D$2:$D$8801,$C18,Pipeline_Completo!$V$2:$V$8801,"Zumbi") -> 63 | P18: =SUMIFS(Pipeline_Completo!$S$2:$S$8801,Pipeline_Completo!$D$2:$D$8801,$C18,Pipeline_Completo!$V$2:$V$8801,"Zumbi") -> 159954 | Q18: =IFERROR(P18/(N18+P18),"") -> 0.7376591 | R18: =COUNTIFS(Pipeline_Completo!$D$2:$D$8801,$C18,Pipeline_Completo!$O$2:$O$8801,"Engaging",Pipeline_Completo!$E$2:$E$8801,"")+COUNTIFS(Pipeline_Completo!$D$2:$D$8801,$C18,Pipeline_Completo!$O$2:$O$8801,"Prospecting",Pipeline_Completo!$E$2:$E$8801,"") -> 54
A19: East | B19: Cara Losch | C19: Rosie Papadopoulos | D19: =COUNTIFS(Pipeline_Completo!$D$2:$D$8801,$C19) -> 160 | E19: =COUNTIFS(Pipeline_Completo!$D$2:$D$8801,$C19,Pipeline_Completo!$O$2:$O$8801,"Won") -> 78 | F19: =COUNTIFS(Pipeline_Completo!$D$2:$D$8801,$C19,Pipeline_Completo!$O$2:$O$8801,"Lost") -> 43 | G19: =COUNTIFS(Pipeline_Completo!$D$2:$D$8801,$C19,Pipeline_Completo!$O$2:$O$8801,"Engaging") -> 39 | H19: =COUNTIFS(Pipeline_Completo!$D$2:$D$8801,$C19,Pipeline_Completo!$O$2:$O$8801,"Prospecting") -> 0 | I19: =IFERROR(E19/(E19+F19),"") -> 0.6446281 | J19: =SUMIFS(Pipeline_Completo!$R$2:$R$8801,Pipeline_Completo!$D$2:$D$8801,$C19,Pipeline_Completo!$O$2:$O$8801,"Won") -> 230169 | K19: =IFERROR(J19/E19,"") -> 2950.8846 | L19: =SUMIFS(Pipeline_Completo!$S$2:$S$8801,Pipeline_Completo!$D$2:$D$8801,$C19,Pipeline_Completo!$O$2:$O$8801,"Engaging")+SUMIFS(Pipeline_Completo!$S$2:$S$8801,Pipeline_Completo!$D$2:$D$8801,$C19,Pipeline_Completo!$O$2:$O$8801,"Prospecting") -> 116685 | M19: =COUNTIFS(Pipeline_Completo!$D$2:$D$8801,$C19,Pipeline_Completo!$V$2:$V$8801,"Saudável")+COUNTIFS(Pipeline_Completo!$D$2:$D$8801,$C19,Pipeline_Completo!$V$2:$V$8801,"Esfriando")+COUNTIFS(Pipeline_Completo!$D$2:$D$8801,$C19,Pipeline_Completo!$V$2:$V$8801,"Última chance") -> 6 | N19: =SUMIFS(Pipeline_Completo!$S$2:$S$8801,Pipeline_Completo!$D$2:$D$8801,$C19,Pipeline_Completo!$V$2:$V$8801,"Saudável")+SUMIFS(Pipeline_Completo!$S$2:$S$8801,Pipeline_Completo!$D$2:$D$8801,$C19,Pipeline_Completo!$V$2:$V$8801,"Esfriando")+SUMIFS(Pipeline_Completo!$S$2:$S$8801,Pipeline_Completo!$D$2:$D$8801,$C19,Pipeline_Completo!$V$2:$V$8801,"Última chance") -> 23227 | O19: =COUNTIFS(Pipeline_Completo!$D$2:$D$8801,$C19,Pipeline_Completo!$V$2:$V$8801,"Zumbi") -> 33 | P19: =SUMIFS(Pipeline_Completo!$S$2:$S$8801,Pipeline_Completo!$D$2:$D$8801,$C19,Pipeline_Completo!$V$2:$V$8801,"Zumbi") -> 93458 | Q19: =IFERROR(P19/(N19+P19),"") -> 0.80094271 | R19: =COUNTIFS(Pipeline_Completo!$D$2:$D$8801,$C19,Pipeline_Completo!$O$2:$O$8801,"Engaging",Pipeline_Completo!$E$2:$E$8801,"")+COUNTIFS(Pipeline_Completo!$D$2:$D$8801,$C19,Pipeline_Completo!$O$2:$O$8801,"Prospecting",Pipeline_Completo!$E$2:$E$8801,"") -> 24
A20: East | B20: Cara Losch | C20: Garret Kinder | D20: =COUNTIFS(Pipeline_Completo!$D$2:$D$8801,$C20) -> 123 | E20: =COUNTIFS(Pipeline_Completo!$D$2:$D$8801,$C20,Pipeline_Completo!$O$2:$O$8801,"Won") -> 75 | F20: =COUNTIFS(Pipeline_Completo!$D$2:$D$8801,$C20,Pipeline_Completo!$O$2:$O$8801,"Lost") -> 48 | G20: =COUNTIFS(Pipeline_Completo!$D$2:$D$8801,$C20,Pipeline_Completo!$O$2:$O$8801,"Engaging") -> 0 | H20: =COUNTIFS(Pipeline_Completo!$D$2:$D$8801,$C20,Pipeline_Completo!$O$2:$O$8801,"Prospecting") -> 0 | I20: =IFERROR(E20/(E20+F20),"") -> 0.6097561 | J20: =SUMIFS(Pipeline_Completo!$R$2:$R$8801,Pipeline_Completo!$D$2:$D$8801,$C20,Pipeline_Completo!$O$2:$O$8801,"Won") -> 197773 | K20: =IFERROR(J20/E20,"") -> 2636.9733 | L20: =SUMIFS(Pipeline_Completo!$S$2:$S$8801,Pipeline_Completo!$D$2:$D$8801,$C20,Pipeline_Completo!$O$2:$O$8801,"Engaging")+SUMIFS(Pipeline_Completo!$S$2:$S$8801,Pipeline_Completo!$D$2:$D$8801,$C20,Pipeline_Completo!$O$2:$O$8801,"Prospecting") -> 0 | M20: =COUNTIFS(Pipeline_Completo!$D$2:$D$8801,$C20,Pipeline_Completo!$V$2:$V$8801,"Saudável")+COUNTIFS(Pipeline_Completo!$D$2:$D$8801,$C20,Pipeline_Completo!$V$2:$V$8801,"Esfriando")+COUNTIFS(Pipeline_Completo!$D$2:$D$8801,$C20,Pipeline_Completo!$V$2:$V$8801,"Última chance") -> 0 | N20: =SUMIFS(Pipeline_Completo!$S$2:$S$8801,Pipeline_Completo!$D$2:$D$8801,$C20,Pipeline_Completo!$V$2:$V$8801,"Saudável")+SUMIFS(Pipeline_Completo!$S$2:$S$8801,Pipeline_Completo!$D$2:$D$8801,$C20,Pipeline_Completo!$V$2:$V$8801,"Esfriando")+SUMIFS(Pipeline_Completo!$S$2:$S$8801,Pipeline_Completo!$D$2:$D$8801,$C20,Pipeline_Completo!$V$2:$V$8801,"Última chance") -> 0 | O20: =COUNTIFS(Pipeline_Completo!$D$2:$D$8801,$C20,Pipeline_Completo!$V$2:$V$8801,"Zumbi") -> 0 | P20: =SUMIFS(Pipeline_Completo!$S$2:$S$8801,Pipeline_Completo!$D$2:$D$8801,$C20,Pipeline_Completo!$V$2:$V$8801,"Zumbi") -> 0 | Q20: =IFERROR(P20/(N20+P20),"") | R20: =COUNTIFS(Pipeline_Completo!$D$2:$D$8801,$C20,Pipeline_Completo!$O$2:$O$8801,"Engaging",Pipeline_Completo!$E$2:$E$8801,"")+COUNTIFS(Pipeline_Completo!$D$2:$D$8801,$C20,Pipeline_Completo!$O$2:$O$8801,"Prospecting",Pipeline_Completo!$E$2:$E$8801,"") -> 0
A21: East | B21: Cara Losch | C21: Wilburn Farren | D21: =COUNTIFS(Pipeline_Completo!$D$2:$D$8801,$C21) -> 110 | E21: =COUNTIFS(Pipeline_Completo!$D$2:$D$8801,$C21,Pipeline_Completo!$O$2:$O$8801,"Won") -> 55 | F21: =COUNTIFS(Pipeline_Completo!$D$2:$D$8801,$C21,Pipeline_Completo!$O$2:$O$8801,"Lost") -> 24 | G21: =COUNTIFS(Pipeline_Completo!$D$2:$D$8801,$C21,Pipeline_Completo!$O$2:$O$8801,"Engaging") -> 31 | H21: =COUNTIFS(Pipeline_Completo!$D$2:$D$8801,$C21,Pipeline_Completo!$O$2:$O$8801,"Prospecting") -> 0 | I21: =IFERROR(E21/(E21+F21),"") -> 0.69620253 | J21: =SUMIFS(Pipeline_Completo!$R$2:$R$8801,Pipeline_Completo!$D$2:$D$8801,$C21,Pipeline_Completo!$O$2:$O$8801,"Won") -> 157640 | K21: =IFERROR(J21/E21,"") -> 2866.1818 | L21: =SUMIFS(Pipeline_Completo!$S$2:$S$8801,Pipeline_Completo!$D$2:$D$8801,$C21,Pipeline_Completo!$O$2:$O$8801,"Engaging")+SUMIFS(Pipeline_Completo!$S$2:$S$8801,Pipeline_Completo!$D$2:$D$8801,$C21,Pipeline_Completo!$O$2:$O$8801,"Prospecting") -> 82275 | M21: =COUNTIFS(Pipeline_Completo!$D$2:$D$8801,$C21,Pipeline_Completo!$V$2:$V$8801,"Saudável")+COUNTIFS(Pipeline_Completo!$D$2:$D$8801,$C21,Pipeline_Completo!$V$2:$V$8801,"Esfriando")+COUNTIFS(Pipeline_Completo!$D$2:$D$8801,$C21,Pipeline_Completo!$V$2:$V$8801,"Última chance") -> 9 | N21: =SUMIFS(Pipeline_Completo!$S$2:$S$8801,Pipeline_Completo!$D$2:$D$8801,$C21,Pipeline_Completo!$V$2:$V$8801,"Saudável")+SUMIFS(Pipeline_Completo!$S$2:$S$8801,Pipeline_Completo!$D$2:$D$8801,$C21,Pipeline_Completo!$V$2:$V$8801,"Esfriando")+SUMIFS(Pipeline_Completo!$S$2:$S$8801,Pipeline_Completo!$D$2:$D$8801,$C21,Pipeline_Completo!$V$2:$V$8801,"Última chance") -> 30795 | O21: =COUNTIFS(Pipeline_Completo!$D$2:$D$8801,$C21,Pipeline_Completo!$V$2:$V$8801,"Zumbi") -> 22 | P21: =SUMIFS(Pipeline_Completo!$S$2:$S$8801,Pipeline_Completo!$D$2:$D$8801,$C21,Pipeline_Completo!$V$2:$V$8801,"Zumbi") -> 51480 | Q21: =IFERROR(P21/(N21+P21),"") -> 0.62570647 | R21: =COUNTIFS(Pipeline_Completo!$D$2:$D$8801,$C21,Pipeline_Completo!$O$2:$O$8801,"Engaging",Pipeline_Completo!$E$2:$E$8801,"")+COUNTIFS(Pipeline_Completo!$D$2:$D$8801,$C21,Pipeline_Completo!$O$2:$O$8801,"Prospecting",Pipeline_Completo!$E$2:$E$8801,"") -> 28
A22: East | B22: Cara Losch | C22: Elizabeth Anderson | D22: =COUNTIFS(Pipeline_Completo!$D$2:$D$8801,$C22) -> 0 | E22: =COUNTIFS(Pipeline_Completo!$D$2:$D$8801,$C22,Pipeline_Completo!$O$2:$O$8801,"Won") -> 0 | F22: =COUNTIFS(Pipeline_Completo!$D$2:$D$8801,$C22,Pipeline_Completo!$O$2:$O$8801,"Lost") -> 0 | G22: =COUNTIFS(Pipeline_Completo!$D$2:$D$8801,$C22,Pipeline_Completo!$O$2:$O$8801,"Engaging") -> 0 | H22: =COUNTIFS(Pipeline_Completo!$D$2:$D$8801,$C22,Pipeline_Completo!$O$2:$O$8801,"Prospecting") -> 0 | I22: =IFERROR(E22/(E22+F22),"") | J22: =SUMIFS(Pipeline_Completo!$R$2:$R$8801,Pipeline_Completo!$D$2:$D$8801,$C22,Pipeline_Completo!$O$2:$O$8801,"Won") -> 0 | K22: =IFERROR(J22/E22,"") | L22: =SUMIFS(Pipeline_Completo!$S$2:$S$8801,Pipeline_Completo!$D$2:$D$8801,$C22,Pipeline_Completo!$O$2:$O$8801,"Engaging")+SUMIFS(Pipeline_Completo!$S$2:$S$8801,Pipeline_Completo!$D$2:$D$8801,$C22,Pipeline_Completo!$O$2:$O$8801,"Prospecting") -> 0 | M22: =COUNTIFS(Pipeline_Completo!$D$2:$D$8801,$C22,Pipeline_Completo!$V$2:$V$8801,"Saudável")+COUNTIFS(Pipeline_Completo!$D$2:$D$8801,$C22,Pipeline_Completo!$V$2:$V$8801,"Esfriando")+COUNTIFS(Pipeline_Completo!$D$2:$D$8801,$C22,Pipeline_Completo!$V$2:$V$8801,"Última chance") -> 0 | N22: =SUMIFS(Pipeline_Completo!$S$2:$S$8801,Pipeline_Completo!$D$2:$D$8801,$C22,Pipeline_Completo!$V$2:$V$8801,"Saudável")+SUMIFS(Pipeline_Completo!$S$2:$S$8801,Pipeline_Completo!$D$2:$D$8801,$C22,Pipeline_Completo!$V$2:$V$8801,"Esfriando")+SUMIFS(Pipeline_Completo!$S$2:$S$8801,Pipeline_Completo!$D$2:$D$8801,$C22,Pipeline_Completo!$V$2:$V$8801,"Última chance") -> 0 | O22: =COUNTIFS(Pipeline_Completo!$D$2:$D$8801,$C22,Pipeline_Completo!$V$2:$V$8801,"Zumbi") -> 0 | P22: =SUMIFS(Pipeline_Completo!$S$2:$S$8801,Pipeline_Completo!$D$2:$D$8801,$C22,Pipeline_Completo!$V$2:$V$8801,"Zumbi") -> 0 | Q22: =IFERROR(P22/(N22+P22),"") | R22: =COUNTIFS(Pipeline_Completo!$D$2:$D$8801,$C22,Pipeline_Completo!$O$2:$O$8801,"Engaging",Pipeline_Completo!$E$2:$E$8801,"")+COUNTIFS(Pipeline_Completo!$D$2:$D$8801,$C22,Pipeline_Completo!$O$2:$O$8801,"Prospecting",Pipeline_Completo!$E$2:$E$8801,"") -> 0
A23: East | B23: Cara Losch | C23: Subtotal Cara Losch | D23: =COUNTIFS(Pipeline_Completo!$C$2:$C$8801,$B23) -> 964 | E23: =COUNTIFS(Pipeline_Completo!$C$2:$C$8801,$B23,Pipeline_Completo!$O$2:$O$8801,"Won") -> 480 | F23: =COUNTIFS(Pipeline_Completo!$C$2:$C$8801,$B23,Pipeline_Completo!$O$2:$O$8801,"Lost") -> 265 | G23: =COUNTIFS(Pipeline_Completo!$C$2:$C$8801,$B23,Pipeline_Completo!$O$2:$O$8801,"Engaging") -> 219 | H23: =COUNTIFS(Pipeline_Completo!$C$2:$C$8801,$B23,Pipeline_Completo!$O$2:$O$8801,"Prospecting") -> 0 | I23: =IFERROR(E23/(E23+F23),"") -> 0.6442953 | J23: =SUMIFS(Pipeline_Completo!$R$2:$R$8801,Pipeline_Completo!$C$2:$C$8801,$B23,Pipeline_Completo!$O$2:$O$8801,"Won") -> 1130049 | K23: =IFERROR(J23/E23,"") -> 2354.2688 | L23: =SUMIFS(Pipeline_Completo!$S$2:$S$8801,Pipeline_Completo!$C$2:$C$8801,$B23,Pipeline_Completo!$O$2:$O$8801,"Engaging")+SUMIFS(Pipeline_Completo!$S$2:$S$8801,Pipeline_Completo!$C$2:$C$8801,$B23,Pipeline_Completo!$O$2:$O$8801,"Prospecting") -> 495950 | M23: =COUNTIFS(Pipeline_Completo!$C$2:$C$8801,$B23,Pipeline_Completo!$V$2:$V$8801,"Saudável")+COUNTIFS(Pipeline_Completo!$C$2:$C$8801,$B23,Pipeline_Completo!$V$2:$V$8801,"Esfriando")+COUNTIFS(Pipeline_Completo!$C$2:$C$8801,$B23,Pipeline_Completo!$V$2:$V$8801,"Última chance") -> 50 | N23: =SUMIFS(Pipeline_Completo!$S$2:$S$8801,Pipeline_Completo!$C$2:$C$8801,$B23,Pipeline_Completo!$V$2:$V$8801,"Saudável")+SUMIFS(Pipeline_Completo!$S$2:$S$8801,Pipeline_Completo!$C$2:$C$8801,$B23,Pipeline_Completo!$V$2:$V$8801,"Esfriando")+SUMIFS(Pipeline_Completo!$S$2:$S$8801,Pipeline_Completo!$C$2:$C$8801,$B23,Pipeline_Completo!$V$2:$V$8801,"Última chance") -> 123514 | O23: =COUNTIFS(Pipeline_Completo!$C$2:$C$8801,$B23,Pipeline_Completo!$V$2:$V$8801,"Zumbi") -> 169 | P23: =SUMIFS(Pipeline_Completo!$S$2:$S$8801,Pipeline_Completo!$C$2:$C$8801,$B23,Pipeline_Completo!$V$2:$V$8801,"Zumbi") -> 372436 | Q23: =IFERROR(P23/(N23+P23),"") -> 0.75095473 | R23: =COUNTIFS(Pipeline_Completo!$C$2:$C$8801,$B23,Pipeline_Completo!$O$2:$O$8801,"Engaging",Pipeline_Completo!$E$2:$E$8801,"")+COUNTIFS(Pipeline_Completo!$C$2:$C$8801,$B23,Pipeline_Completo!$O$2:$O$8801,"Prospecting",Pipeline_Completo!$E$2:$E$8801,"") -> 154
A24: East | B24: Rocco Neubert | C24: Daniell Hammack | D24: =COUNTIFS(Pipeline_Completo!$D$2:$D$8801,$C24) -> 259 | E24: =COUNTIFS(Pipeline_Completo!$D$2:$D$8801,$C24,Pipeline_Completo!$O$2:$O$8801,"Won") -> 114 | F24: =COUNTIFS(Pipeline_Completo!$D$2:$D$8801,$C24,Pipeline_Completo!$O$2:$O$8801,"Lost") -> 73 | G24: =COUNTIFS(Pipeline_Completo!$D$2:$D$8801,$C24,Pipeline_Completo!$O$2:$O$8801,"Engaging") -> 72 | H24: =COUNTIFS(Pipeline_Completo!$D$2:$D$8801,$C24,Pipeline_Completo!$O$2:$O$8801,"Prospecting") -> 0 | I24: =IFERROR(E24/(E24+F24),"") -> 0.60962567 | J24: =SUMIFS(Pipeline_Completo!$R$2:$R$8801,Pipeline_Completo!$D$2:$D$8801,$C24,Pipeline_Completo!$O$2:$O$8801,"Won") -> 364229 | K24: =IFERROR(J24/E24,"") -> 3194.9912 | L24: =SUMIFS(Pipeline_Completo!$S$2:$S$8801,Pipeline_Completo!$D$2:$D$8801,$C24,Pipeline_Completo!$O$2:$O$8801,"Engaging")+SUMIFS(Pipeline_Completo!$S$2:$S$8801,Pipeline_Completo!$D$2:$D$8801,$C24,Pipeline_Completo!$O$2:$O$8801,"Prospecting") -> 209320 | M24: =COUNTIFS(Pipeline_Completo!$D$2:$D$8801,$C24,Pipeline_Completo!$V$2:$V$8801,"Saudável")+COUNTIFS(Pipeline_Completo!$D$2:$D$8801,$C24,Pipeline_Completo!$V$2:$V$8801,"Esfriando")+COUNTIFS(Pipeline_Completo!$D$2:$D$8801,$C24,Pipeline_Completo!$V$2:$V$8801,"Última chance") -> 21 | N24: =SUMIFS(Pipeline_Completo!$S$2:$S$8801,Pipeline_Completo!$D$2:$D$8801,$C24,Pipeline_Completo!$V$2:$V$8801,"Saudável")+SUMIFS(Pipeline_Completo!$S$2:$S$8801,Pipeline_Completo!$D$2:$D$8801,$C24,Pipeline_Completo!$V$2:$V$8801,"Esfriando")+SUMIFS(Pipeline_Completo!$S$2:$S$8801,Pipeline_Completo!$D$2:$D$8801,$C24,Pipeline_Completo!$V$2:$V$8801,"Última chance") -> 54302 | O24: =COUNTIFS(Pipeline_Completo!$D$2:$D$8801,$C24,Pipeline_Completo!$V$2:$V$8801,"Zumbi") -> 51 | P24: =SUMIFS(Pipeline_Completo!$S$2:$S$8801,Pipeline_Completo!$D$2:$D$8801,$C24,Pipeline_Completo!$V$2:$V$8801,"Zumbi") -> 155018 | Q24: =IFERROR(P24/(N24+P24),"") -> 0.74057902 | R24: =COUNTIFS(Pipeline_Completo!$D$2:$D$8801,$C24,Pipeline_Completo!$O$2:$O$8801,"Engaging",Pipeline_Completo!$E$2:$E$8801,"")+COUNTIFS(Pipeline_Completo!$D$2:$D$8801,$C24,Pipeline_Completo!$O$2:$O$8801,"Prospecting",Pipeline_Completo!$E$2:$E$8801,"") -> 47
A25: East | B25: Rocco Neubert | C25: Cassey Cress | D25: =COUNTIFS(Pipeline_Completo!$D$2:$D$8801,$C25) -> 346 | E25: =COUNTIFS(Pipeline_Completo!$D$2:$D$8801,$C25,Pipeline_Completo!$O$2:$O$8801,"Won") -> 163 | F25: =COUNTIFS(Pipeline_Completo!$D$2:$D$8801,$C25,Pipeline_Completo!$O$2:$O$8801,"Lost") -> 98 | G25: =COUNTIFS(Pipeline_Completo!$D$2:$D$8801,$C25,Pipeline_Completo!$O$2:$O$8801,"Engaging") -> 85 | H25: =COUNTIFS(Pipeline_Completo!$D$2:$D$8801,$C25,Pipeline_Completo!$O$2:$O$8801,"Prospecting") -> 0 | I25: =IFERROR(E25/(E25+F25),"") -> 0.62452107 | J25: =SUMIFS(Pipeline_Completo!$R$2:$R$8801,Pipeline_Completo!$D$2:$D$8801,$C25,Pipeline_Completo!$O$2:$O$8801,"Won") -> 450489 | K25: =IFERROR(J25/E25,"") -> 2763.7362 | L25: =SUMIFS(Pipeline_Completo!$S$2:$S$8801,Pipeline_Completo!$D$2:$D$8801,$C25,Pipeline_Completo!$O$2:$O$8801,"Engaging")+SUMIFS(Pipeline_Completo!$S$2:$S$8801,Pipeline_Completo!$D$2:$D$8801,$C25,Pipeline_Completo!$O$2:$O$8801,"Prospecting") -> 220860 | M25: =COUNTIFS(Pipeline_Completo!$D$2:$D$8801,$C25,Pipeline_Completo!$V$2:$V$8801,"Saudável")+COUNTIFS(Pipeline_Completo!$D$2:$D$8801,$C25,Pipeline_Completo!$V$2:$V$8801,"Esfriando")+COUNTIFS(Pipeline_Completo!$D$2:$D$8801,$C25,Pipeline_Completo!$V$2:$V$8801,"Última chance") -> 23 | N25: =SUMIFS(Pipeline_Completo!$S$2:$S$8801,Pipeline_Completo!$D$2:$D$8801,$C25,Pipeline_Completo!$V$2:$V$8801,"Saudável")+SUMIFS(Pipeline_Completo!$S$2:$S$8801,Pipeline_Completo!$D$2:$D$8801,$C25,Pipeline_Completo!$V$2:$V$8801,"Esfriando")+SUMIFS(Pipeline_Completo!$S$2:$S$8801,Pipeline_Completo!$D$2:$D$8801,$C25,Pipeline_Completo!$V$2:$V$8801,"Última chance") -> 48662 | O25: =COUNTIFS(Pipeline_Completo!$D$2:$D$8801,$C25,Pipeline_Completo!$V$2:$V$8801,"Zumbi") -> 62 | P25: =SUMIFS(Pipeline_Completo!$S$2:$S$8801,Pipeline_Completo!$D$2:$D$8801,$C25,Pipeline_Completo!$V$2:$V$8801,"Zumbi") -> 172198 | Q25: =IFERROR(P25/(N25+P25),"") -> 0.77967038 | R25: =COUNTIFS(Pipeline_Completo!$D$2:$D$8801,$C25,Pipeline_Completo!$O$2:$O$8801,"Engaging",Pipeline_Completo!$E$2:$E$8801,"")+COUNTIFS(Pipeline_Completo!$D$2:$D$8801,$C25,Pipeline_Completo!$O$2:$O$8801,"Prospecting",Pipeline_Completo!$E$2:$E$8801,"") -> 56
A26: East | B26: Rocco Neubert | C26: Donn Cantrell | D26: =COUNTIFS(Pipeline_Completo!$D$2:$D$8801,$C26) -> 275 | E26: =COUNTIFS(Pipeline_Completo!$D$2:$D$8801,$C26,Pipeline_Completo!$O$2:$O$8801,"Won") -> 158 | F26: =COUNTIFS(Pipeline_Completo!$D$2:$D$8801,$C26,Pipeline_Completo!$O$2:$O$8801,"Lost") -> 117 | G26: =COUNTIFS(Pipeline_Completo!$D$2:$D$8801,$C26,Pipeline_Completo!$O$2:$O$8801,"Engaging") -> 0 | H26: =COUNTIFS(Pipeline_Completo!$D$2:$D$8801,$C26,Pipeline_Completo!$O$2:$O$8801,"Prospecting") -> 0 | I26: =IFERROR(E26/(E26+F26),"") -> 0.57454545 | J26: =SUMIFS(Pipeline_Completo!$R$2:$R$8801,Pipeline_Completo!$D$2:$D$8801,$C26,Pipeline_Completo!$O$2:$O$8801,"Won") -> 445860 | K26: =IFERROR(J26/E26,"") -> 2821.8987 | L26: =SUMIFS(Pipeline_Completo!$S$2:$S$8801,Pipeline_Completo!$D$2:$D$8801,$C26,Pipeline_Completo!$O$2:$O$8801,"Engaging")+SUMIFS(Pipeline_Completo!$S$2:$S$8801,Pipeline_Completo!$D$2:$D$8801,$C26,Pipeline_Completo!$O$2:$O$8801,"Prospecting") -> 0 | M26: =COUNTIFS(Pipeline_Completo!$D$2:$D$8801,$C26,Pipeline_Completo!$V$2:$V$8801,"Saudável")+COUNTIFS(Pipeline_Completo!$D$2:$D$8801,$C26,Pipeline_Completo!$V$2:$V$8801,"Esfriando")+COUNTIFS(Pipeline_Completo!$D$2:$D$8801,$C26,Pipeline_Completo!$V$2:$V$8801,"Última chance") -> 0 | N26: =SUMIFS(Pipeline_Completo!$S$2:$S$8801,Pipeline_Completo!$D$2:$D$8801,$C26,Pipeline_Completo!$V$2:$V$8801,"Saudável")+SUMIFS(Pipeline_Completo!$S$2:$S$8801,Pipeline_Completo!$D$2:$D$8801,$C26,Pipeline_Completo!$V$2:$V$8801,"Esfriando")+SUMIFS(Pipeline_Completo!$S$2:$S$8801,Pipeline_Completo!$D$2:$D$8801,$C26,Pipeline_Completo!$V$2:$V$8801,"Última chance") -> 0 | O26: =COUNTIFS(Pipeline_Completo!$D$2:$D$8801,$C26,Pipeline_Completo!$V$2:$V$8801,"Zumbi") -> 0 | P26: =SUMIFS(Pipeline_Completo!$S$2:$S$8801,Pipeline_Completo!$D$2:$D$8801,$C26,Pipeline_Completo!$V$2:$V$8801,"Zumbi") -> 0 | Q26: =IFERROR(P26/(N26+P26),"") | R26: =COUNTIFS(Pipeline_Completo!$D$2:$D$8801,$C26,Pipeline_Completo!$O$2:$O$8801,"Engaging",Pipeline_Completo!$E$2:$E$8801,"")+COUNTIFS(Pipeline_Completo!$D$2:$D$8801,$C26,Pipeline_Completo!$O$2:$O$8801,"Prospecting",Pipeline_Completo!$E$2:$E$8801,"") -> 0
A27: East | B27: Rocco Neubert | C27: Reed Clapper | D27: =COUNTIFS(Pipeline_Completo!$D$2:$D$8801,$C27) -> 237 | E27: =COUNTIFS(Pipeline_Completo!$D$2:$D$8801,$C27,Pipeline_Completo!$O$2:$O$8801,"Won") -> 155 | F27: =COUNTIFS(Pipeline_Completo!$D$2:$D$8801,$C27,Pipeline_Completo!$O$2:$O$8801,"Lost") -> 82 | G27: =COUNTIFS(Pipeline_Completo!$D$2:$D$8801,$C27,Pipeline_Completo!$O$2:$O$8801,"Engaging") -> 0 | H27: =COUNTIFS(Pipeline_Completo!$D$2:$D$8801,$C27,Pipeline_Completo!$O$2:$O$8801,"Prospecting") -> 0 | I27: =IFERROR(E27/(E27+F27),"") -> 0.65400844 | J27: =SUMIFS(Pipeline_Completo!$R$2:$R$8801,Pipeline_Completo!$D$2:$D$8801,$C27,Pipeline_Completo!$O$2:$O$8801,"Won") -> 438336 | K27: =IFERROR(J27/E27,"") -> 2827.9742 | L27: =SUMIFS(Pipeline_Completo!$S$2:$S$8801,Pipeline_Completo!$D$2:$D$8801,$C27,Pipeline_Completo!$O$2:$O$8801,"Engaging")+SUMIFS(Pipeline_Completo!$S$2:$S$8801,Pipeline_Completo!$D$2:$D$8801,$C27,Pipeline_Completo!$O$2:$O$8801,"Prospecting") -> 0 | M27: =COUNTIFS(Pipeline_Completo!$D$2:$D$8801,$C27,Pipeline_Completo!$V$2:$V$8801,"Saudável")+COUNTIFS(Pipeline_Completo!$D$2:$D$8801,$C27,Pipeline_Completo!$V$2:$V$8801,"Esfriando")+COUNTIFS(Pipeline_Completo!$D$2:$D$8801,$C27,Pipeline_Completo!$V$2:$V$8801,"Última chance") -> 0 | N27: =SUMIFS(Pipeline_Completo!$S$2:$S$8801,Pipeline_Completo!$D$2:$D$8801,$C27,Pipeline_Completo!$V$2:$V$8801,"Saudável")+SUMIFS(Pipeline_Completo!$S$2:$S$8801,Pipeline_Completo!$D$2:$D$8801,$C27,Pipeline_Completo!$V$2:$V$8801,"Esfriando")+SUMIFS(Pipeline_Completo!$S$2:$S$8801,Pipeline_Completo!$D$2:$D$8801,$C27,Pipeline_Completo!$V$2:$V$8801,"Última chance") -> 0 | O27: =COUNTIFS(Pipeline_Completo!$D$2:$D$8801,$C27,Pipeline_Completo!$V$2:$V$8801,"Zumbi") -> 0 | P27: =SUMIFS(Pipeline_Completo!$S$2:$S$8801,Pipeline_Completo!$D$2:$D$8801,$C27,Pipeline_Completo!$V$2:$V$8801,"Zumbi") -> 0 | Q27: =IFERROR(P27/(N27+P27),"") | R27: =COUNTIFS(Pipeline_Completo!$D$2:$D$8801,$C27,Pipeline_Completo!$O$2:$O$8801,"Engaging",Pipeline_Completo!$E$2:$E$8801,"")+COUNTIFS(Pipeline_Completo!$D$2:$D$8801,$C27,Pipeline_Completo!$O$2:$O$8801,"Prospecting",Pipeline_Completo!$E$2:$E$8801,"") -> 0
A28: East | B28: Rocco Neubert | C28: Boris Faz | D28: =COUNTIFS(Pipeline_Completo!$D$2:$D$8801,$C28) -> 210 | E28: =COUNTIFS(Pipeline_Completo!$D$2:$D$8801,$C28,Pipeline_Completo!$O$2:$O$8801,"Won") -> 101 | F28: =COUNTIFS(Pipeline_Completo!$D$2:$D$8801,$C28,Pipeline_Completo!$O$2:$O$8801,"Lost") -> 52 | G28: =COUNTIFS(Pipeline_Completo!$D$2:$D$8801,$C28,Pipeline_Completo!$O$2:$O$8801,"Engaging") -> 57 | H28: =COUNTIFS(Pipeline_Completo!$D$2:$D$8801,$C28,Pipeline_Completo!$O$2:$O$8801,"Prospecting") -> 0 | I28: =IFERROR(E28/(E28+F28),"") -> 0.66013072 | J28: =SUMIFS(Pipeline_Completo!$R$2:$R$8801,Pipeline_Completo!$D$2:$D$8801,$C28,Pipeline_Completo!$O$2:$O$8801,"Won") -> 261631 | K28: =IFERROR(J28/E28,"") -> 2590.4059 | L28: =SUMIFS(Pipeline_Completo!$S$2:$S$8801,Pipeline_Completo!$D$2:$D$8801,$C28,Pipeline_Completo!$O$2:$O$8801,"Engaging")+SUMIFS(Pipeline_Completo!$S$2:$S$8801,Pipeline_Completo!$D$2:$D$8801,$C28,Pipeline_Completo!$O$2:$O$8801,"Prospecting") -> 143456 | M28: =COUNTIFS(Pipeline_Completo!$D$2:$D$8801,$C28,Pipeline_Completo!$V$2:$V$8801,"Saudável")+COUNTIFS(Pipeline_Completo!$D$2:$D$8801,$C28,Pipeline_Completo!$V$2:$V$8801,"Esfriando")+COUNTIFS(Pipeline_Completo!$D$2:$D$8801,$C28,Pipeline_Completo!$V$2:$V$8801,"Última chance") -> 13 | N28: =SUMIFS(Pipeline_Completo!$S$2:$S$8801,Pipeline_Completo!$D$2:$D$8801,$C28,Pipeline_Completo!$V$2:$V$8801,"Saudável")+SUMIFS(Pipeline_Completo!$S$2:$S$8801,Pipeline_Completo!$D$2:$D$8801,$C28,Pipeline_Completo!$V$2:$V$8801,"Esfriando")+SUMIFS(Pipeline_Completo!$S$2:$S$8801,Pipeline_Completo!$D$2:$D$8801,$C28,Pipeline_Completo!$V$2:$V$8801,"Última chance") -> 34180 | O28: =COUNTIFS(Pipeline_Completo!$D$2:$D$8801,$C28,Pipeline_Completo!$V$2:$V$8801,"Zumbi") -> 44 | P28: =SUMIFS(Pipeline_Completo!$S$2:$S$8801,Pipeline_Completo!$D$2:$D$8801,$C28,Pipeline_Completo!$V$2:$V$8801,"Zumbi") -> 109276 | Q28: =IFERROR(P28/(N28+P28),"") -> 0.76173879 | R28: =COUNTIFS(Pipeline_Completo!$D$2:$D$8801,$C28,Pipeline_Completo!$O$2:$O$8801,"Engaging",Pipeline_Completo!$E$2:$E$8801,"")+COUNTIFS(Pipeline_Completo!$D$2:$D$8801,$C28,Pipeline_Completo!$O$2:$O$8801,"Prospecting",Pipeline_Completo!$E$2:$E$8801,"") -> 39
